Workbook

Sheet 일자별 누계
A2: 세로 막대형1 | B2: 세로 막대형2 | C2: 세로 막대형5 | D2: 세로 막대형6 | E2: 세로 막대형7 | F2: 세로 막대형8 | G2: 세로 막대형9 | H2: 세로 막대형10 | I2: 세로 막대형11 | J2: 세로 막대형12 | K2: 세로 막대형13 | L2: 세로 막대형14 | M2: 세로 막대형15 | N2: 세로 막대형16 | O2: 세로 막대형17 | P2: 세로 막대형18 | Q2: 세로 막대형19 | R2: 세로 막대형20 | S2: 최종
A3: 일반 계열 | B3: 모집단위 | D3: 일자
C4: 2026학년도 | D4: 45968 | E4: 45969 | F4: 45970 | G4: 45971 | H4: 45972 | I4: 45973 | J4: 45974 | K4: 45975 | L4: 45976 | M4: 45977 | N4: 45978 | O4: 45979 | P4: 45980 | Q4: 45981 | R4: 45982
A5: 공학 | B5: 자유전공학부 | C5: 12 | D5: =IF($D$4='학과별 원서접수'!$F$2,'학과별 원서접수'!F4,"아직") -> 아직 | E5: =IF($E$4='학과별 원서접수'!$F$2,'학과별 원서접수'!G4,"아직") -> 아직 | F5: =IF($F$4='학과별 원서접수'!$F$2,'학과별 원서접수'!H4,"아직") -> 아직 | G5: =IF($G$4='학과별 원서접수'!$F$2,'학과별 원서접수'!I4,"아직") -> 아직 | H5: =IF($H$4='학과별 원서접수'!$F$2,'학과별 원서접수'!J4,"아직") -> 0 | I5: =IF(I4='학과별 원서접수'!$F$2,'학과별 원서접수'!K4,"아직") -> 아직 | J5: =IF(J4='학과별 원서접수'!$F$2,'학과별 원서접수'!L4,"아직") -> 아직 | K5: =IF(K4='학과별 원서접수'!$F$2,'학과별 원서접수'!M4,"아직") -> 아직 | L5: =IF(L4='학과별 원서접수'!$F$2,'학과별 원서접수'!N4,"아직") -> 아직 | M5: =IF(M4='학과별 원서접수'!$F$2,'학과별 원서접수'!O4,"아직") -> 아직 | N5: =IF(N4='학과별 원서접수'!$F$2,'학과별 원서접수'!P4,"아직") -> 아직 | O5: =IF(O4='학과별 원서접수'!$F$2,'학과별 원서접수'!Q4,"아직") -> 아직 | P5: =IF(P4='학과별 원서접수'!$F$2,'학과별 원서접수'!R4,"아직") -> 아직 | ... R5: =IF(R4='학과별 원서접수'!$F$2,'학과별 원서접수'!T4,"아직") -> 아직
A6: 공학 | B6: 기계공학과 | C6: 18 | D6: =IF($D$4='학과별 원서접수'!$F$2,'학과별 원서접수'!F5,"아직") -> 아직 | E6: =IF($E$4='학과별 원서접수'!$F$2,'학과별 원서접수'!G5,"아직") -> 아직 | F6: =IF($F$4='학과별 원서접수'!$F$2,'학과별 원서접수'!H5,"아직") -> 아직 | G6: =IF($G$4='학과별 원서접수'!$F$2,'학과별 원서접수'!I5,"아직") -> 아직 | H6: =IF($H$4='학과별 원서접수'!$F$2,'학과별 원서접수'!J5,"아직") -> 0
A7: 공학 | B7: 기계설계공학과 | C7: 18 | D7: =IF($D$4='학과별 원서접수'!$F$2,'학과별 원서접수'!F6,"아직") -> 아직 | E7: =IF($E$4='학과별 원서접수'!$F$2,'학과별 원서접수'!G6,"아직") -> 아직 | F7: =IF($F$4='학과별 원서접수'!$F$2,'학과별 원서접수'!H6,"아직") -> 아직 | G7: =IF($G$4='학과별 원서접수'!$F$2,'학과별 원서접수'!I6,"아직") -> 아직 | H7: =IF($H$4='학과별 원서접수'!$F$2,'학과별 원서접수'!J6,"아직") -> 0
A8: 공학 | B8: 로봇자동화공학과 | C8: 16 | D8: =IF($D$4='학과별 원서접수'!$F$2,'학과별 원서접수'!F7,"아직") -> 아직 | E8: =IF($E$4='학과별 원서접수'!$F$2,'학과별 원서접수'!G7,"아직") -> 아직 | F8: =IF($F$4='학과별 원서접수'!$F$2,'학과별 원서접수'!H7,"아직") -> 아직 | G8: =IF($G$4='학과별 원서접수'!$F$2,'학과별 원서접수'!I7,"아직") -> 아직 | H8: =IF($H$4='학과별 원서접수'!$F$2,'학과별 원서접수'!J7,"아직") -> 0
A9: 공학 | B9: 반도체기계정비학과 | C9: 9 | D9: =IF($D$4='학과별 원서접수'!$F$2,'학과별 원서접수'!F8,"아직") -> 아직 | E9: =IF($E$4='학과별 원서접수'!$F$2,'학과별 원서접수'!G8,"아직") -> 아직 | F9: =IF($F$4='학과별 원서접수'!$F$2,'학과별 원서접수'!H8,"아직") -> 아직 | G9: =IF($G$4='학과별 원서접수'!$F$2,'학과별 원서접수'!I8,"아직") -> 아직 | H9: =IF($H$4='학과별 원서접수'!$F$2,'학과별 원서접수'!J8,"아직") -> 0
A10: 공학 | B10: 조선기계공학과 | C10: 18 | D10: =IF($D$4='학과별 원서접수'!$F$2,'학과별 원서접수'!F9,"아직") -> 아직 | E10: =IF($E$4='학과별 원서접수'!$F$2,'학과별 원서접수'!G9,"아직") -> 아직 | F10: =IF($F$4='학과별 원서접수'!$F$2,'학과별 원서접수'!H9,"아직") -> 아직 | G10: =IF($G$4='학과별 원서접수'!$F$2,'학과별 원서접수'!I9,"아직") -> 아직 | H10: =IF($H$4='학과별 원서접수'!$F$2,'학과별 원서접수'!J9,"아직") -> 0
A11: 공학 | B11: 항공기계공학과 | C11: 18 | D11: =IF($D$4='학과별 원서접수'!$F$2,'학과별 원서접수'!F10,"아직") -> 아직 | E11: =IF($E$4='학과별 원서접수'!$F$2,'학과별 원서접수'!G10,"아직") -> 아직 | F11: =IF($F$4='학과별 원서접수'!$F$2,'학과별 원서접수'!H10,"아직") -> 아직 | G11: =IF($G$4='학과별 원서접수'!$F$2,'학과별 원서접수'!I10,"아직") -> 아직 | H11: =IF($H$4='학과별 원서접수'!$F$2,'학과별 원서접수'!J10,"아직") -> 0
A12: 공학 | B12: 자동차공학과 | C12: 15 | D12: =IF($D$4='학과별 원서접수'!$F$2,'학과별 원서접수'!F11,"아직") -> 아직 | E12: =IF($E$4='학과별 원서접수'!$F$2,'학과별 원서접수'!G11,"아직") -> 아직 | F12: =IF($F$4='학과별 원서접수'!$F$2,'학과별 원서접수'!H11,"아직") -> 아직 | G12: =IF($G$4='학과별 원서접수'!$F$2,'학과별 원서접수'!I11,"아직") -> 아직 | H12: =IF($H$4='학과별 원서접수'!$F$2,'학과별 원서접수'!J11,"아직") -> 0
A13: 공학 | B13: 전기공학과 | C13: 16 | D13: =IF($D$4='학과별 원서접수'!$F$2,'학과별 원서접수'!F12,"아직") -> 아직 | E13: =IF($E$4='학과별 원서접수'!$F$2,'학과별 원서접수'!G12,"아직") -> 아직 | F13: =IF($F$4='학과별 원서접수'!$F$2,'학과별 원서접수'!H12,"아직") -> 아직 | G13: =IF($G$4='학과별 원서접수'!$F$2,'학과별 원서접수'!I12,"아직") -> 아직 | H13: =IF($H$4='학과별 원서접수'!$F$2,'학과별 원서접수'!J12,"아직") -> 0
A14: 공학 | B14: 전자공학과 | C14: 18 | D14: =IF($D$4='학과별 원서접수'!$F$2,'학과별 원서접수'!F13,"아직") -> 아직 | E14: =IF($E$4='학과별 원서접수'!$F$2,'학과별 원서접수'!G13,"아직") -> 아직 | F14: =IF($F$4='학과별 원서접수'!$F$2,'학과별 원서접수'!H13,"아직") -> 아직 | G14: =IF($G$4='학과별 원서접수'!$F$2,'학과별 원서접수'!I13,"아직") -> 아직 | H14: =IF($H$4='학과별 원서접수'!$F$2,'학과별 원서접수'!J13,"아직") -> 0
A15: 공학 | B15: 정보통신공학과 | C15: 24 | D15: =IF($D$4='학과별 원서접수'!$F$2,'학과별 원서접수'!F14,"아직") -> 아직 | E15: =IF($E$4='학과별 원서접수'!$F$2,'학과별 원서접수'!G14,"아직") -> 아직 | F15: =IF($F$4='학과별 원서접수'!$F$2,'학과별 원서접수'!H14,"아직") -> 아직 | G15: =IF($G$4='학과별 원서접수'!$F$2,'학과별 원서접수'!I14,"아직") -> 아직 | H15: =IF($H$4='학과별 원서접수'!$F$2,'학과별 원서접수'!J14,"아직") -> 0
A16: 공학 | B16: 컴퓨터정보공학과 | C16: 19 | D16: =IF($D$4='학과별 원서접수'!$F$2,'학과별 원서접수'!F15,"아직") -> 아직 | E16: =IF($E$4='학과별 원서접수'!$F$2,'학과별 원서접수'!G15,"아직") -> 아직 | F16: =IF($F$4='학과별 원서접수'!$F$2,'학과별 원서접수'!H15,"아직") -> 아직 | G16: =IF($G$4='학과별 원서접수'!$F$2,'학과별 원서접수'!I15,"아직") -> 아직 | H16: =IF($H$4='학과별 원서접수'!$F$2,'학과별 원서접수'!J15,"아직") -> 0
A17: 공학 | B17: 컴퓨터시스템공학과 | C17: 18 | D17: =IF($D$4='학과별 원서접수'!$F$2,'학과별 원서접수'!F16,"아직") -> 아직 | E17: =IF($E$4='학과별 원서접수'!$F$2,'학과별 원서접수'!G16,"아직") -> 아직 | F17: =IF($F$4='학과별 원서접수'!$F$2,'학과별 원서접수'!H16,"아직") -> 아직 | G17: =IF($G$4='학과별 원서접수'!$F$2,'학과별 원서접수'!I16,"아직") -> 아직 | H17: =IF($H$4='학과별 원서접수'!$F$2,'학과별 원서접수'!J16,"아직") -> 0
... A33: 예체능 | B33: 스포츠헬스케어학과 | C33: 12 | D33: =IF($D$4='학과별 원서접수'!$F$2,'학과별 원서접수'!F32,"아직") -> 아직 | E33: =IF($E$4='학과별 원서접수'!$F$2,'학과별 원서접수'!G32,"아직") -> 아직 | F33: =IF($F$4='학과별 원서접수'!$F$2,'학과별 원서접수'!H32,"아직") -> 아직 | G33: =IF($G$4='학과별 원서접수'!$F$2,'학과별 원서접수'!I32,"아직") -> 아직 | H33: =IF($H$4='학과별 원서접수'!$F$2,'학과별 원서접수'!J32,"아직") -> 0
A34: 총계 | B34: 총계 | C34: 498 | D34: =SUBTOTAL(109,D5:D33) -> 0 | E34: =IF($E$4='학과별 원서접수'!$F$2,'학과별 원서접수'!G33,"아직") -> 아직 | F34: =SUBTOTAL(109,F5:F33) -> 0 | G34: =SUBTOTAL(109,G5:G33) -> 0 | H34: =SUBTOTAL(109,H5:H33) -> 0 | I34: =SUBTOTAL(109,I5:I33) -> 0 | J34: =SUBTOTAL(109,J5:J33) -> 0 | K34: =SUBTOTAL(109,K5:K33) -> 0 | L34: =SUBTOTAL(109,L5:L33) -> 0 | M34: =SUBTOTAL(109,M5:M33) -> 0 | ... R34: =SUBTOTAL(109,R5:R33) -> 0
A38: 세로 막대형1 | B38: 세로 막대형2 | C38: 세로 막대형5 | D38: 세로 막대형6 | E38: 세로 막대형7 | F38: 세로 막대형8 | G38: 세로 막대형9 | H38: 세로 막대형10 | I38: 세로 막대형11 | J38: 세로 막대형12 | K38: 세로 막대형13 | L38: 세로 막대형14 | M38: 세로 막대형15 | N38: 세로 막대형16 | O38: 세로 막대형17 | P38: 세로 막대형18 | Q38: 세로 막대형19 | R38: 세로 막대형20 | S38: 최종
A39: 일반 계열 | B39: 모집단위 | D39: 일자
C40: 2026학년도 | D40: 45968 | E40: 45969 | F40: 45970 | G40: 45971 | H40: 45972 | I40: 45973 | J40: 45974 | K40: 45975 | L40: 45976 | M40: 45977 | N40: 45978 | O40: 45979 | P40: 45980 | Q40: 45981 | R40: 45982
A41: 공학 | B41: 자유전공학부 | C41: 16 | D41: 아직 | E41: 아직 | F41: 아직 | H41: 아직 | I41: 아직 | J41: 아직 | K41: 아직 | L41: 아직 | M41: 아직 | N41: 아직 | O41: 아직 | P41: 아직 | Q41: 아직 | R41: 아직 | S41: 10
A42: 공학 | B42: 기계공학과 | C42: 23 | D42: 아직 | E42: 아직 | F42: 아직 | S42: 21
A43: 공학 | B43: 기계설계공학과 | C43: 23 | D43: 아직 | E43: 아직 | F43: 아직 | S43: 12
A44: 공학 | B44: 로봇자동화공학과 | C44: 20 | D44: 아직 | E44: 아직 | F44: 아직 | S44: 6
A45: 공학 | B45: 반도체기계정비학과 | C45: 15 | D45: 아직 | E45: 아직 | F45: 아직 | S45: 11
A46: 공학 | B46: 조선기계공학과 | C46: 23 | D46: 아직 | E46: 아직 | F46: 아직 | S46: 23
A47: 공학 | B47: 항공기계공학과 | C47: 30 | D47: 아직 | E47: 아직 | F47: 아직 | S47: 28
A48: 공학 | B48: 자동차공학과 | C48: 23 | D48: 아직 | E48: 아직 | F48: 아직 | S48: 22
A49: 공학 | B49: 전기공학과 | C49: 21 | D49: 아직 | E49: 아직 | F49: 아직 | S49: 28
A50: 공학 | B50: 전자공학과 | C50: 23 | D50: 아직 | E50: 아직 | F50: 아직 | S50: 20
A51: 공학 | B51: 정보통신공학과 | C51: 30 | D51: 아직 | E51: 아직 | F51: 아직 | S51: 7
A52: 공학 | B52: 컴퓨터정보공학과 | C52: 23 | D52: 아직 | E52: 아직 | F52: 아직 | S52: 6
A53: 공학 | B53: 컴퓨터시스템공학과 | C53: 23 | D53: 아직 | E53: 아직 | F53: 아직 | S53: 12
... A69: 예체능 | B69: 스포츠헬스케어학과 | C69: 15 | D69: 아직 | E69: 아직 | F69: 아직 | S69: 19
A70: 총계 | B70: 총계 | C70: 644 | D70: 369 | E70: 155 | F70: 162 | G70: 21 | H70: 0 | I70: 0 | J70: 0 | K70: 0 | L70: 0 | M70: 0 | N70: 0 | O70: 0 | P70: 0 | Q70: 0 | R70: 0 | S70: 619

Sheet 2026학년도 대학별 수시2차 지원현황
B2: ● 원서접수 결과표(정원내 모집 기준) | X2: =TODAY() -> 45972 | AT2: =X2 -> 45972
B3: 대학명 | C3: 입학정원 | G3: 모집인원 | K3: 지원자 | O3: 경쟁률 | S3: 정원내•외 전체 | X3: 대학명 | Y3: 입학정원 | AC3: 모집인원 | AG3: 지원자 | AK3: 경쟁률 | AO3: 정원내•외 전체 | AT3: 대학명 | AU3: 정원내•외 전체
C4: 2024 | D4: 2025 | E4: 2026 | F4: 증감 | G4: 2024 | H4: 2025 | I4: 2026 | J4: 증감 | K4: 2024 | L4: 2025 | M4: 2026 | N4: 증감 | O4: 2024 | P4: 2025 | Q4: 2026 | R4: 증감 | S4: 2024 | T4: 2025 | U4: 2026 | V4: 증감 | Y4: 2024 | Z4: 2025 | AA4: 2024 | AB4: 증감 | AC4: 2024 | AD4: 2025 | AE4: 2026 | AF4: 증감 | AG4: 2024 | AH4: 2025 | AI4: 2026 | AJ4: 증감 | AK4: 2024 | AL4: 2025 | AM4: 2026 | AN4: 증감 | AO4: 2024 | AP4: 2025 | AQ4: 2026 | AR4: 증감 | AU4: 2024 | AV4: 2025 | AW4: 2026 | AX4: 전년 대비 증감
B5: 인하공업전문대학 | C5: 2553 | D5: 2543 | E5: 2543 | F5: =D5-E5 -> 0 | G5: 639 | H5: 644 | I5: 644 | J5: =H5-I5 -> 0 | K5: 5853 | L5: 6259 | M5: =전형별_경쟁률_현황__3[[#This Row],[지원인원]] -> 822 | N5: =L5-M5 -> 5437 | O5: 9.1596244 | P5: 9.7189441 | Q5: =LEFTB(전형별_경쟁률_현황__3[[#This Row],[경쟁률]],4) -> 1.28 | R5: =P5-Q5 -> 8.4389441 | S5: 6308 | T5: 6697 | U5: ='학과별 원서접수 데이터'!E10 -> 916 | V5: 389 | X5: 인하공업전문대학 | Y5: 2553 | Z5: 2543 | AA5: 5853 | AB5: =Z5-AA5 -> -3310 | AC5: 639 | AD5: 644 | AE5: 644 | AF5: =AD5-AE5 -> 0 | AG5: 5853 | AH5: 6259 | AI5: =M5 -> 822 | AJ5: =AH5-AI5 -> 5437 | AK5: 9.1596244 | AL5: 9.7189441 | AM5: =LEFTB(전형별_경쟁률_현황__3[[#This Row],[경쟁률]],4) -> 1.28 | AN5: =AL5-AM5 -> 8.4389441 | AO5: 6308 | AP5: 6697 | AQ5: =U5 -> 916 | AR5: =AP5-AQ5 -> 5781 | AT5: 인하공업전문대학 | AU5: 6308 | AV5: 6697 | AW5: =AQ5 -> 916 | AX5: =AV5-AW5 -> 5781
B6: 동양미래대학교 | C6: 2235 | D6: 2115 | E6: 2135 | F6: =D6-E6 -> -20 | G6: 654 | H6: 622 | I6: 620 | J6: =H6-I6 -> 2 | K6: 3806 | L6: 3712 | M6: ='학과별 원서접수 데이터'!C14+'학과별 원서접수 데이터'!C15 -> 350 | N6: =L6-M6 -> 3362 | O6: 5.8195719 | P6: 5.9678457 | Q6: =LEFTB('학과별 원서접수 데이터'!D17,4) -> 0.47 | R6: =P6-Q6 -> 5.4978457 | S6: 3818 | T6: 3734 | U6: ='학과별 원서접수 데이터'!C17 -> 353 | V6: -84 | X6: 동양미래대학교 | Y6: 2235 | Z6: 2115 | AA6: 3806 | AB6: =Z6-AA6 -> -1691 | AC6: 654 | AD6: 622 | AE6: 620 | AF6: =AD6-AE6 -> 2 | AG6: 3806 | AH6: 3712 | AI6: =M6 -> 350 | AJ6: =AH6-AI6 -> 3362 | AK6: 5.8195719 | AL6: 5.9678457 | AM6: =LEFTB('학과별 원서접수 데이터'!D17,4) -> 0.47 | AN6: =AL6-AM6 -> 5.4978457 | AO6: 3818 | AP6: 3734 | AQ6: =U6 -> 353 | AR6: =AP6-AQ6 -> 3381 | AT6: 동양미래대학교 | AU6: 3818 | AV6: 3734 | AW6: =AQ6 -> 353 | AX6: =AV6-AW6 -> 3381
B7: 한양여자대학교M | C7: 2426 | D7: 2280 | E7: 2314 | F7: =D7-E7 -> -34 | G7: 697 | H7: 640 | I7: 659 | J7: =H7-I7 -> -19 | K7: 5464 | L7: 6725 | M7: ='학과별 원서접수 데이터'!C21 -> 614 | N7: =L7-M7 -> 6111 | O7: 7.8393113 | P7: 10.507812 | Q7: =LEFTB('학과별 원서접수 데이터'!D23,4) -> 0.89 | R7: =P7-Q7 -> 9.6178125 | S7: 5527 | T7: 6827 | U7: ='학과별 원서접수 데이터'!C23 -> 639 | V7: 1300 | X7: 한양여자대학교M | Y7: 2426 | Z7: 2280 | AA7: 5464 | AB7: =Z7-AA7 -> -3184 | AC7: 697 | AD7: 640 | AE7: 659 | AF7: =AD7-AE7 -> -19 | AG7: 5464 | AH7: 6725 | AI7: =M7 -> 614 | AJ7: =AH7-AI7 -> 6111 | AK7: 7.8393113 | AL7: 10.507812 | AM7: =Q7 -> 0.89 | AN7: =AL7-AM7 -> 9.6178125 | AO7: 5527 | AP7: 6827 | AQ7: =U7 -> 639 | AR7: =AP7-AQ7 -> 6188 | AT7: 한양여자대학교M | AU7: 5527 | AV7: 6827 | AW7: =AQ7 -> 639 | AX7: =AV7-AW7 -> 6188
B8: 동서울대학교M | C8: 2289 | D8: 2289 | E8: 2226 | F8: =D8-E8 -> 63 | G8: 329 | H8: 342 | I8: 376 | J8: =H8-I8 -> -34 | K8: 2905 | L8: 3414 | M8: =전체_경쟁률_현황__2[지원인원] -> 464 | N8: =L8-M8 -> 2950 | O8: 8.8297872 | P8: 9.9824561 | Q8: =LEFTB(전체_경쟁률_현황__2[경쟁률],4) -> 1.23 | R8: =P8-Q8 -> 8.7524561 | S8: 2905 | T8: 3414 | U8: =전체_경쟁률_현황__2[지원인원] -> 464 | V8: 509 | X8: 동서울대학교M | Y8: 2289 | Z8: 2289 | AA8: 2905 | AB8: =Z8-AA8 -> -616 | AC8: 329 | AD8: 342 | AE8: 376 | AF8: =AD8-AE8 -> -34 | AG8: 2905 | AH8: 3414 | AI8: =M8 -> 464 | AJ8: =AH8-AI8 -> 2950 | AK8: 8.8297872 | AL8: 9.9824561 | AM8: =Q8 -> 1.23 | AN8: =AL8-AM8 -> 8.7524561 | AO8: 2905 | AP8: 3414 | AQ8: =U8 -> 464 | AR8: =AP8-AQ8 -> 2950 | AT8: 동서울대학교M | AU8: 2905 | AV8: 3414 | AW8: =AQ8 -> 464 | AX8: =AV8-AW8 -> 2950
B9: 연성대학교M | C9: 2212 | D9: 2216 | E9: 2191 | F9: =D9-E9 -> 25 | G9: 583 | H9: 590 | I9: 587 | J9: =H9-I9 -> 3 | K9: 5672 | L9: 7008 | M9: ='학과별 원서접수 데이터'!D36 -> 1121 | N9: =L9-M9 -> 5887 | O9: 9.728988 | P9: 11.877966 | Q9: =LEFTB('학과별 원서접수 데이터'!E41,4) -> 1.86 | R9: =P9-Q9 -> 10.017966 | S9: 5676 | T9: 7019 | U9: ='학과별 원서접수 데이터'!D41 -> 1151 | V9: 1343 | X9: 연성대학교M | Y9: 2212 | Z9: 2216 | AA9: 5672 | AB9: =Z9-AA9 -> -3456 | AC9: 583 | AD9: 590 | AE9: 587 | AF9: =AD9-AE9 -> 3 | AG9: 5672 | AH9: 7008 | AI9: =M9 -> 1121 | AJ9: =AH9-AI9 -> 5887 | AK9: 9.728988 | AL9: 11.877966 | AM9: =Q9 -> 1.86 | AN9: =AL9-AM9 -> 10.017966 | AO9: 5676 | AP9: 7019 | AQ9: =U9 -> 1151 | AR9: =AP9-AQ9 -> 5868 | AT9: 연성대학교M | AU9: 5676 | AV9: 7019 | AW9: =AQ9 -> 1151 | AX9: =AV9-AW9 -> 5868
B10: 부천대학교 | C10: 2191 | D10: 2181 | E10: 2130 | F10: =D10-E10 -> 51 | G10: 642 | H10: 623 | I10: 579 | J10: =H10-I10 -> 44 | K10: 6531 | L10: 6407 | M10: ='학과별 원서접수 데이터'!N5 -> 818 | N10: =L10-M10 -> 5589 | O10: 10.172897 | P10: 10.284109 | Q10: =LEFTB('학과별 원서접수 데이터'!O5,4) -> 1.41 | R10: =P10-Q10 -> 8.8741091 | S10: 6924 | T10: 6827 | U10: =전형별_경쟁률_현황__7[[#This Row],[지원인원]] -> 906 | V10: -97 | X10: 부천대학교 | Y10: 2191 | Z10: 2181 | AA10: 6531 | AB10: =Z10-AA10 -> -4350 | AC10: 642 | AD10: 623 | AE10: 579 | AF10: =AD10-AE10 -> 44 | AG10: 6531 | AH10: 6407 | AI10: =M10 -> 818 | AJ10: =AH10-AI10 -> 5589 | AK10: 10.172897 | AL10: 10.284109 | AM10: =Q10 -> 1.41 | AN10: =AL10-AM10 -> 8.8741091 | AO10: 6924 | AP10: 6827 | AQ10: =U10 -> 906 | AR10: =AP10-AQ10 -> 5921 | AT10: 부천대학교 | AU10: 6924 | AV10: 6827 | AW10: =AQ10 -> 906 | AX10: =AV10-AW10 -> 5921
B11: 대림대학교M | C11: 2167 | D11: 2164 | E11: 2190 | F11: =D11-E11 -> -26 | G11: 468 | H11: 468 | I11: 480 | J11: =H11-I11 -> -12 | K11: 2322 | L11: 3388 | M11: =전체_경쟁률_현황__3[지원인원] -> 479 | N11: =L11-M11 -> 2909 | O11: 4.9615385 | P11: 7.2393162 | Q11: =LEFTB(전체_경쟁률_현황__3[지원율],4) -> 0.93 | R11: =P11-Q11 -> 6.3093162 | S11: 2436 | T11: 3534 | U11: =전체_경쟁률_현황__3[지원인원] -> 479 | V11: 1098 | X11: 대림대학교M | Y11: 2167 | Z11: 2164 | AA11: 2322 | AB11: =Z11-AA11 -> -158 | AC11: 468 | AD11: 468 | AE11: 480 | AF11: =AD11-AE11 -> -12 | AG11: 2322 | AH11: 3388 | AI11: =M11 -> 479 | AJ11: =AH11-AI11 -> 2909 | AK11: 4.9615385 | AL11: 7.2393162 | AM11: =Q11 -> 0.93 | AN11: =AL11-AM11 -> 6.3093162 | AO11: 2436 | AP11: 3534 | AQ11: =U11 -> 479 | AR11: =AP11-AQ11 -> 3055 | AT11: 대림대학교M | AU11: 2436 | AV11: 3534 | AW11: =AQ11 -> 479 | AX11: =AV11-AW11 -> 3055
B12: 유한대학교 | C12: 1703 | D12: 1695 | E12: 1691 | F12: =D12-E12 -> 4 | G12: 231 | H12: 212 | I12: 263 | J12: =H12-I12 -> -51 | K12: 2745 | L12: 3120 | M12: ='학과별 원서접수 데이터'!N21 -> 467 | N12: =L12-M12 -> 2653 | O12: 11.883117 | P12: 14.716981 | Q12: =LEFTB('학과별 원서접수 데이터'!O28,4) -> 1.19 | R12: =P12-Q12 -> 13.526981 | S12: 2926 | T12: 3307 | U12: ='학과별 원서접수 데이터'!N28 -> 500 | V12: 381 | X12: 유한대학교 | Y12: 1703 | Z12: 1695 | AA12: 2745 | AB12: =Z12-AA12 -> -1050 | AC12: 231 | AD12: 212 | AE12: 263 | AF12: =AD12-AE12 -> -51 | AG12: 2745 | AH12: 3120 | AI12: =M12 -> 467 | AJ12: =AH12-AI12 -> 2653 | AK12: 11.883117 | AL12: 14.716981 | AM12: =Q12 -> 1.19 | AN12: =AL12-AM12 -> 13.526981 | AO12: 2926 | AP12: 3307 | AQ12: =U12 -> 500 | AR12: =AP12-AQ12 -> 2807 | AT12: 유한대학교 | AU12: 2926 | AV12: 3307 | AW12: =AQ12 -> 500 | AX12: =AV12-AW12 -> 2807
B13: 경인여자대학교M | C13: 1305 | D13: 1305 | E13: 1305 | F13: =D13-E13 -> 0 | G13: 242 | H13: 257 | I13: 233 | J13: =H13-I13 -> 24 | K13: 2204 | L13: 2699 | M13: =전체_경쟁률_현황__4[지원인원] -> 333 | N13: =L13-M13 -> 2366 | O13: 9.107438 | P13: 10.501946 | Q13: =LEFTB(전체_경쟁률_현황__4[경쟁률],4) -> 1.17 | R13: =P13-Q13 -> 9.3319455 | S13: 2526 | T13: 2986 | U13: =전체_경쟁률_현황__4[지원인원] -> 333 | V13: 460 | X13: 경인여자대학교M | Y13: 1305 | Z13: 1305 | AA13: 2204 | AB13: =Z13-AA13 -> -899 | AC13: 242 | AD13: 257 | AE13: 233 | AF13: =AD13-AE13 -> 24 | AG13: 2204 | AH13: 2699 | AI13: =M13 -> 333 | AJ13: =AH13-AI13 -> 2366 | AK13: 9.107438 | AL13: 10.501946 | AM13: =Q13 -> 1.17 | AN13: =AL13-AM13 -> 9.3319455 | AO13: 2526 | AP13: 2986 | AQ13: =U13 -> 333 | AR13: =AP13-AQ13 -> 2653 | AT13: 경인여자대학교M | AU13: 2526 | AV13: 2986 | AW13: =AQ13 -> 333 | AX13: =AV13-AW13 -> 2653
B14: 재능대학교M | C14: 1313 | D14: 1279 | E14: 1237 | F14: =D14-E14 -> 42 | G14: 241 | H14: 225 | I14: 214 | J14: =H14-I14 -> 11 | K14: 1751 | L14: 1840 | M14: ='학과별 원서접수 데이터'!N40 -> 318 | N14: =L14-M14 -> 1522 | O14: 7.2655602 | P14: 8.1777778 | Q14: =LEFTB('학과별 원서접수 데이터'!O44,4) -> 1.04 | R14: =P14-Q14 -> 7.1377778 | S14: 1772 | T14: 1868 | U14: ='학과별 원서접수 데이터'!N44 -> 320 | V14: 96 | X14: 재능대학교M | Y14: 1313 | Z14: 1279 | AA14: 1751 | AB14: =Z14-AA14 -> -472 | AC14: 241 | AD14: 225 | AE14: 214 | AF14: =AD14-AE14 -> 11 | AG14: 1751 | AH14: 1840 | AI14: =M14 -> 318 | AJ14: =AH14-AI14 -> 1522 | AK14: 7.2655602 | AL14: 8.1777778 | AM14: =Q14 -> 1.04 | AN14: =AL14-AM14 -> 7.1377778 | AO14: 1772 | AP14: 1868 | AQ14: =U14 -> 320 | AR14: =AP14-AQ14 -> 1548 | AT14: 재능대학교M | AU14: 1772 | AV14: 1868 | AW14: =AQ14 -> 320 | AX14: =AV14-AW14 -> 1548
B15: 김포대학교M | C15: 852 | D15: 822 | E15: 822 | F15: =D15-E15 -> 0 | G15: 293 | H15: 183 | I15: 64 | J15: =H15-I15 -> 119 | K15: 1222 | L15: 1929 | M15: ='학과별 원서접수 데이터'!U63 -> 77 | N15: =L15-M15 -> 1852 | O15: 4.1706485 | P15: 10.540984 | Q15: =LEFTB('학과별 원서접수 데이터'!V37,4) -> 1.12 | R15: =P15-Q15 -> 9.4209836 | S15: 1246 | T15: 1937 | U15: ='학과별 원서접수 데이터'!U63 -> 77 | V15: 691 | X15: 김포대학교M | Y15: 852 | Z15: 822 | AA15: 1222 | AB15: =Z15-AA15 -> -400 | AC15: 293 | AD15: 183 | AE15: 64 | AF15: =AD15-AE15 -> 119 | AG15: 1222 | AH15: 1929 | AI15: =M15 -> 77 | AJ15: =AH15-AI15 -> 1852 | AK15: 4.1706485 | AL15: 10.540984 | AM15: =Q15 -> 1.12 | AN15: =AL15-AM15 -> 9.4209836 | AO15: 1246 | AP15: 1937 | AQ15: =U15 -> 77 | AR15: =AP15-AQ15 -> 1860 | AT15: 김포대학교M | AU15: 1246 | AV15: 1937 | AW15: =AQ15 -> 77 | AX15: =AV15-AW15 -> 1860
B19: ● 정원내•외 지원 현황
B20: ● 원서접수 결과표(정원내 모집 기준)
B21: ● 지역별 지원 현황
B22: ● 경쟁률 상위 학과(일반고, 일반전형 기준)
B23: ● 일자별 원서접수 현황
B24: ● 시간대 원서접수 현황
B25: ● 학과별 원서접수 현황
B31: ● 경쟁률 상위 학과(일반고, 일반전형 기준) | X31: ● 정원내•외 지원 현황
B33: 대학명 | D33: 학과(전공)명
B34: 인하공업전문대학 | D34: 항공운항과, 패션디자인학과, 항공경영학과, 경영비서학과, 항공기계공학과, 스포츠헬스케어학과, 자동차공학과, 전기공학과, 조선기계공학과, 자유전공학부
B35: 동양미래대학교 | D35: 호텔관광학과, 시각디자인과, 소방안전관리과, 전기공학과, 경영학과
B36: 한양여자대학교 | D36: 아동보육과, 실무일본어과, 반려동물보건과, 실무중국어과, 자유전공학과
B37: 동서울대학교 | D37: 디지털방송콘텐츠학과, 게임콘텐츠과, 항공서비스학과, 마케팅과, 호텔관광경영과
B38: 연성대학교 | D38: 항공서비스과, 치위생과, 뷰티스타일리스트과 메이크업전공, 뷰티스타일리스트과 헤어디자인전공, 반려동물보건과
B39: 부천대학교 | D39: 항공서비스과, 치위생학과, 뷰티케어과 헤어디자인전공, 뷰티케어과 뷰티디자인전공, 간호학과
B40: 대림대학교 | D40: 항공호텔관광과, 보건의료행정과, 응급구조과, 응용SW전공, 사무행정학과
B41: 유한대학교 | D41: 항공서비스학과, 애니메이션웹툰전공, 경영정보전공, 응급구조과, 호텔관광전공
B42: 경인여자대학교(일반) | D42: 항공서비스학과, 치위생학과, 호텔관광학과, 응급구조학과, 사회복지학과
B43: 재능대학교 | D43: 간호학과, 항공서비스과, 보건의료행정과, 스포츠재활과, 드론영상과
B44: 김포대학교 | D44: 경영학과, 철도경영과, 자유전공학과, 사회복지과, 부동산과

Sheet 학과별 원서접수 데이터
A1: 구분 | B1: 전형명 | C1: 전형명2 | D1: 모집인원 | E1: 지원인원 | F1: 경쟁률 | G1: 인하공업전문대학 | J1: 부천대학교 | K1: 구분 | L1: 전형 | M1: 총모집인원 | N1: 지원인원 | O1: 경쟁률 | R1: 인하공업전문대학 | S1: https://addon.jinhakapply.com/RatioV1/RatioH/Ratio41260471.html
A2: 정원내 | B2: 일반고 | C2: 일반고 | D2: 498 | E2: 601 | F2: 1.21 : 1 | K2: 정원 내 특별전형 | L2: 일반고 | M2: 447 | N2: 620 | O2: 1.39 : 1 | R2: 동양미래대학교 | S2: https://addon.jinhakapply.com/RatioV1/RatioH/Ratio40580371.html
A3: 정원내 | B3: 특성화고 | C3: 특성화고 | D3: 137 | E3: 199 | F3: 1.45 : 1 | K3: 정원 내 특별전형 | L3: 특성화고 | M3: 114 | N3: 165 | O3: 1.45 : 1 | R3: 한양여자대학교M | S3: https://ratio.uwayapply.com/SmZKVzhNYU5ifEpmQ0NhTEotZlRm
A4: 정원내 | B4: 특기자(어학) | C4: 특기자(어학) | D4: 9 | E4: 22 | F4: 2.44 : 1 | K4: 정원 내 특별전형 | L4: 특기자 | M4: 18 | N4: 33 | O4: 1.83 : 1 | R4: 동서울대학교M | S4: https://ratio.uwayapply.com/SmZKOlZKZkNDYUxKLWZUZg==
A5: 소계 | B5: 소계 | C5: 소계 | D5: 644 | E5: 822 | F5: 1.28 : 1 | K5: 정원 내 특별전형 소계 | L5: 정원 내 특별전형 소계 | M5: 579 | N5: 818 | O5: 1.41 : 1 | R5: 연성대학교M | S5: https://ratio.uwayapply.com/SmZKclc6JldhYGJKZkNDYUxKLWZUZg==
A6: 정원외 | B6: 농어촌 | C6: 농어촌 | D6: 30 | E6: 22 | F6: 0.73 : 1 | K6: 정원 외 특별전형 | L6: 수급자 및 차상위 | M6: 18 | N6: 32 | O6: 1.78 : 1 | R6: 부천대학교 | S6: https://ratio.uwayapply.com/SmZKTEJKZkNDYUxKLWZUZg==
A7: 정원외 | B7: 수급자 | C7: 수급자 | D7: 53 | E7: 61 | F7: 1.15 : 1 | K7: 정원 외 특별전형 | L7: 농어촌 | M7: 7 | N7: 4 | O7: 0.57 : 1 | R7: 대림대학교M | S7: https://ratio.uwayapply.com/SmZKTSVDYDhWSmZDQ2FMSi1mVGY=
A8: 정원외 | B8: 전문대졸 이상 | C8: 전문대졸 이상 | D8: 제한없음 | E8: 11 | K8: 정원 외 특별전형 | L8: 전문대이상 졸업자 | M8: 63 | N8: 52 | O8: 0.83 : 1 | R8: 유한대학교 | S8: https://ratio.uwayapply.com/SmZKVzh8OmJKZkNDYUxKLWZUZg==
A9: 정원외 | B9: 북한이탈주민 | C9: 북한이탈주민 | D9: 제한없음 | E9: 0 | K9: 정원 외 특별전형 소계 | L9: 정원 외 특별전형 소계 | M9: 88 | N9: 88 | O9: 1.00 : 1 | R9: 경인여자대학교M | S9: https://addon.jinhakapply.com/RatioV1/RatioH/Ratio40180641.html
A10: 지원인원 총계 | B10: 지원인원 총계 | C10: 지원인원 총계 | D10: 지원인원 총계 | E10: 916 | K10: 총계 | L10: 총계 | M10: 667 | N10: 906 | O10: 1.36 : 1 | R10: 재능대학교M | S10: https://addon.jinhakapply.com/RatioV1/RatioH/Ratio41290851.html
R11: 김포대학교M | S11: https://info.kimpo.ac.kr/Smart/Ent/Entrance/S/SISS10P.aspx
A13: 전형명 | B13: 모집인원 | C13: 지원인원 | D13: 경쟁률 | G13: 동양미래대학교
A14: 일반고 전형 | B14: 509 | C14: 242 | D14: 0.48 : 1 | J14: 대림대학교M | K14: 구분 | L14: 총모집인원 | M14: 지원인원 | N14: 지원율
A15: 특성화고 전형 | B15: 111 | C15: 108 | D15: 0.97 : 1 | K15: 총계 | L15: 517 | M15: 479 | N15: 0.93 : 1 | R15: Column1 | S15: Column2 | T15: Column3 | U15: Column4 | V15: Column5 | W15: Column6 | X15: Column7 | Y15: Column8 | Z15: Column9 | AA15: Column10 | AB15: Column11 | AC15: Column12 | AD15: Column13 | AE15: Column14 | AF15: Column15 | AG15: Column16 | AH15: Column17
A16: 전문대학이상 졸업자 전형 | B16: 138 | C16: 3 | D16: 0.02 : 1 | R16: 계열없음 | S16: 유아교육과(3)★ | T16: 1 | U16: 5 | V16: 5.00 | W16: - | X16: - | Y16: - | Z16: - | AA16: - | AB16: - | AC16: 2 | AD16: - | AE16: - | AF16: - | AG16: - | AH16: -
A17: 총계 | B17: 758 | C17: 353 | D17: 0.47 : 1 | R17: 미래융합계열_x000D_ (모집인원:16명) | S17: 실용음악과(3)★◈ | T17: 15 | U17: 1 | V17: 0.07 | W17: - | X17: - | Y17: - | Z17: 1 | AA17: - | AB17: - | AC17: 1 | AD17: - | AE17: - | AF17: - | AG17: - | AH17: -
J18: 유한대학교 | K18: 구분 | L18: 모집전형 | M18: 모집인원 | N18: 지원인원 | O18: 경쟁률 | R18: 미래융합계열_x000D_ (모집인원:16명) | S18: 보건행정과(3)★ | T18: - | U18: - | V18: - | W18: 1 | X18: 2 | Y18: 2.00 | Z18: 1 | AA18: - | AB18: - | AC18: 1 | AD18: - | AE18: - | AF18: - | AG18: - | AH18: -
K19: 정원내 | L19: 일반고 전형 | M19: 206 | N19: 336 | O19: 1.63 : 1 | R19: 미래융합계열_x000D_ (모집인원:16명) | S19: 게임콘텐츠과(3) | T19: - | U19: - | V19: - | W19: 1 | X19: - | Y19: 2.00 | Z19: 1 | AA19: - | AB19: - | AC19: 1 | AD19: - | AE19: - | AF19: - | AG19: - | AH19: -
A20: 구분 | B20: 총모집인원 | C20: 지원인원 | D20: 경쟁률 | G20: 한양여자대학교M | K20: 정원내 | L20: 특성화고 전형 | M20: 57 | N20: 131 | O20: 2.30 : 1 | R20: 창의융합계열_x000D_ (모집인원:53명) | S20: 글로벌실용무용과★◈ | T20: 10 | U20: - | V20: - | W20: - | X20: - | Y20: - | Z20: 1 | AA20: - | AB20: - | AC20: - | AD20: - | AE20: - | AF20: - | AG20: - | AH20: -
A21: 정원 내 | B21: 659 | C21: 614 | D21: 0.93 : 1 | K21: 소계 | L21: 소계 | M21: 263 | N21: 467 | O21: 1.78 : 1 | R21: 창의융합계열_x000D_ (모집인원:53명) | S21: 레저스포츠과★◈ | T21: 20 | U21: 16 | V21: 0.80 | W21: - | X21: - | Y21: - | Z21: 1 | AA21: - | AB21: - | AC21: - | AD21: - | AE21: - | AF21: - | AG21: - | AH21: -
A22: 정원 외 | B22: 60 | C22: 25 | D22: 0.42 : 1 | K22: 정원외 | L22: 전문대학 이상 졸업자 전형 | M22: 제한없음 | N22: 6 | O22: - | R22: 창의융합계열_x000D_ (모집인원:53명) | S22: 태권도융합과★◈ | T22: 15 | U22: 12 | V22: 0.80 | W22: - | X22: - | Y22: - | Z22: 1 | AA22: - | AB22: - | AC22: - | AD22: - | AE22: - | AF22: - | AG22: - | AH22: -
A23: 총계 | B23: 719 | C23: 639 | D23: 0.89 : 1 | K23: 정원외 | L23: 기초생활수급자 및 차상위계층 전형 | M23: 34 | N23: 27 | O23: 0.79 : 1 | R23: 창의융합계열_x000D_ (모집인원:53명) | S23: 무도경호과 | T23: 7 | U23: - | V23: 1.29 | W23: 1 | X23: 1 | Y23: 1.00 | Z23: 1 | AA23: - | AB23: - | AC23: - | AD23: - | AE23: - | AF23: - | AG23: - | AH23: -
K24: 정원외 | L24: 외국인/북한이탈주민 전형 | M24: 제한없음 | N24: 0 | O24: - | R24: 창의융합계열_x000D_ (모집인원:53명) | S24: 연기과 | T24: 7 | U24: - | V24: 1.29 | W24: 1 | X24: - | Y24: 1.00 | Z24: 1 | AA24: - | AB24: - | AC24: - | AD24: - | AE24: - | AF24: - | AG24: - | AH24: -
K25: 정원외 | L25: 재외국민 전형 | M25: 33 | N25: 0 | O25: 0.00 : 1 | R25: 창의융합계열_x000D_ (모집인원:53명) | S25: 유튜브크리에이터과 | T25: 7 | U25: - | V25: 1.29 | W25: 1 | X25: - | Y25: 1.00 | Z25: 1 | AA25: - | AB25: - | AC25: - | AD25: - | AE25: - | AF25: - | AG25: - | AH25: -
A26: 구분 | B26: 총모집인원 | C26: 지원인원 | D26: 경쟁률 | G26: 동서울대학교M | K26: 정원외 | L26: 재직자 전형(특성화고 등을 졸업한 재직자) | M26: 88 | N26: 0 | O26: 0.00 : 1 | R26: 창의융합계열_x000D_ (모집인원:53명) | S26: 융합전공학과 | T26: 7 | U26: 9 | V26: 1.29 | W26: 1 | X26: - | Y26: 1.00 | Z26: 1 | AA26: - | AB26: - | AC26: - | AD26: - | AE26: - | AF26: - | AG26: - | AH26: -
A27: 총계 | B27: 376 | C27: 464 | D27: 1.23 : 1 | K27: 소계 | L27: 소계 | M27: 158 | N27: 33 | O27: 0.21 : 1 | R27: 창의융합계열_x000D_ (모집인원:53명) | S27: AI융합학과_x000D_ (외국인전담학과)★ | T27: - | U27: - | V27: - | W27: - | X27: - | Y27: - | Z27: - | AA27: - | AB27: - | AC27: - | AD27: - | AE27: - | AF27: - | AG27: - | AH27: -
K28: 합계 | L28: 합계 | M28: 421 | N28: 500 | O28: 1.19 : 1 | R28: 창의융합계열_x000D_ (모집인원:53명) | S28: 너싱케어학과_x000D_ (외국인전담학과) | T28: - | U28: - | V28: - | W28: - | X28: - | Y28: - | Z28: - | AA28: - | AB28: - | AC28: - | AD28: - | AE28: - | AF28: - | AG28: - | AH28: -
R29: 혁신융합계열_x000D_ (모집인원:1명) | S29: 뷰티아트과 | T29: 1 | U29: 12 | V29: 34.00 | W29: - | X29: - | Y29: - | Z29: 1 | AA29: - | AB29: - | AC29: 5 | AD29: - | AE29: 0.20 | AF29: - | AG29: - | AH29: -
R30: 혁신융합계열_x000D_ (모집인원:1명) | S30: 호텔제과제빵과 | T30: 1 | U30: 2 | V30: 34.00 | W30: - | X30: - | Y30: - | Z30: 1 | AA30: - | AB30: - | AC30: 5 | AD30: - | AE30: 0.20 | AF30: - | AG30: - | AH30: -
A31: 구분 | B31: 전형 | C31: 총모집인원 | D31: 지원인원 | E31: 경쟁률 | G31: 연성대학교M | J31: 경인여자대학교M | K31: 구분 | L31: 총모집인원 | M31: 지원인원 | N31: 경쟁률 | R31: 혁신융합계열_x000D_ (모집인원:1명) | S31: 경찰행정과 | T31: 1 | U31: 12 | V31: 34.00 | W31: - | X31: - | Y31: - | Z31: 1 | AA31: - | AB31: - | AC31: 5 | AD31: 1 | AE31: 0.20 | AF31: - | AG31: - | AH31: -
A32: 정원내 | B32: 일반전형 | C32: 79 | D32: 122 | E32: 1.54 : 1 | K32: 총계 | L32: 285 | M32: 333 | N32: 1.17 : 1 | R32: 혁신융합계열_x000D_ (모집인원:1명) | S32: 사회복지과 | T32: 1 | U32: 4 | V32: 34.00 | W32: - | X32: - | Y32: - | Z32: 1 | AA32: - | AB32: - | AC32: 5 | AD32: - | AE32: 0.20 | AF32: - | AG32: - | AH32: -
A33: 정원내 | B33: 특별전형-일반고 | C33: 346 | D33: 735 | E33: 2.12 : 1 | R33: 혁신융합계열_x000D_ (모집인원:1명) | S33: 아동보육과★ | T33: 1 | U33: - | V33: 34.00 | W33: - | X33: - | Y33: - | Z33: 1 | AA33: - | AB33: - | AC33: 5 | AD33: - | AE33: 0.20 | AF33: - | AG33: - | AH33: -
A34: 정원내 | B34: 특별전형-특성화고 | C34: 149 | D34: 202 | E34: 1.36 : 1 | R34: 혁신융합계열_x000D_ (모집인원:1명) | S34: 철도경영과 | T34: 1 | U34: 2 | V34: 34.00 | W34: - | X34: - | Y34: - | Z34: 1 | AA34: - | AB34: - | AC34: 5 | AD34: - | AE34: 0.20 | AF34: - | AG34: - | AH34: -
A35: 정원내 | B35: 대학자체 | C35: 13 | D35: 62 | E35: 4.77 : 1 | J35: 재능대학교M | K35: 구분 | L35: 전형명 | M35: 모집인원 | N35: 지원인원 | O35: 경쟁률 | R35: 혁신융합계열_x000D_ (모집인원:1명) | S35: 부동산과 | T35: 1 | U35: - | V35: 34.00 | W35: - | X35: - | Y35: - | Z35: 1 | AA35: - | AB35: - | AC35: 5 | AD35: - | AE35: 0.20 | AF35: - | AG35: - | AH35: -
A36: 정원내 소계 | B36: 정원내 소계 | C36: 587 | D36: 1121 | E36: 1.91 : 1 | K36: 정원내 | L36: 일반고전형 | M36: 141 | N36: 220 | O36: 1.56 : 1 | R36: 혁신융합계열_x000D_ (모집인원:1명) | S36: 자유전공학과 | T36: 1 | U36: 2 | V36: 34.00 | W36: - | X36: - | Y36: - | Z36: 1 | AA36: - | AB36: - | AC36: 5 | AD36: - | AE36: 0.20 | AF36: - | AG36: - | AH36: -
A37: 정원외 | B37: 기초수급 및 차상위 | C37: 2 | D37: 6 | E37: 3.00 : 1 | K37: 정원내 | L37: 특성화고전형 | M37: 55 | N37: 86 | O37: 1.56 : 1 | R37: 합 계 | S37: 합 계 | T37: 69 | U37: 77 | V37: 1.12 | W37: 2 | X37: 3 | Y37: 1.50 | Z37: 3 | AA37: - | AB37: - | AC37: 8 | AD37: 1 | AE37: 0.13 | AF37: - | AG37: - | AH37: -
A38: 정원외 | B38: 농어촌 | C38: 5 | D38: 3 | E38: 0.60 : 1 | K38: 정원내 | L38: 실기전형 | M38: 18 | N38: 12 | O38: 0.67 : 1
A39: 정원외 | B39: 전문대이상졸업자 | C39: 25 | D39: 21 | E39: 0.84 : 1 | K39: 정원내 | L39: 소계 | M39: 214 | N39: 318 | O39: 1.49 : 1
A40: 정원외 소계 | B40: 정원외 소계 | C40: 32 | D40: 30 | E40: 0.94 : 1 | K40: 정원내 소계 | L40: 정원내 소계 | M40: 214 | N40: 318 | O40: 1.49 : 1
A41: 총계 | B41: 총계 | C41: 619 | D41: 1151 | E41: 1.86 : 1 | K41: 정원외 | L41: [정원외] 전문대졸이상졸업자전형 | M41: 87 | N41: 2 | O41: 0.02 : 1 | R41: Column1 | S41: Column2 | T41: Column3 | U41: Column4 | V41: Column5
...

Sheet 정원내•외 지원 현황
A1: ● 원서접수 결과표(정원내 모집 기준)
A2: 대학명 | B2: 입학정원 | F2: 모집인원 | J2: 지원자 | N2: 경쟁률 | Q2: 정원내•외 전체
B3: 2024 | C3: 2025 | D3: 2026 | E3: 증감 | F3: 2024 | G3: 2025 | H3: 2026 | I3: 증감 | J3: 2024 | K3: 2025 | L3: 2026 | M3: 증감 | N3: 2024 | O3: 2025 | P3: 증감 | Q3: 2024 | R3: 2025 | S3: 2026 | T3: 증감
A4: 인하공업전문대학 | B4: 2553 | C4: 2543 | D4: 2543 | E4: -10 | F4: 639 | G4: 644 | H4: 644 | I4: 5 | J4: 5853 | K4: 6259 | L4: ='2026학년도 대학별 수시2차 지원현황'!M5 -> 822 | M4: ='2026학년도 대학별 수시2차 지원현황'!N5 -> 5437 | N4: 9.1596244 | O4: 9.7189441 | P4: 0.55931969 | Q4: 6308 | R4: 6697 | S4: 1 | T4: 389
A5: 동양미래대학교 | B5: 2235 | C5: 2115 | D5: 2135 | E5: -120 | F5: 654 | G5: 622 | H5: 620 | I5: -32 | J5: 3806 | K5: 3712 | L5: ='2026학년도 대학별 수시2차 지원현황'!M6 -> 350 | M5: ='2026학년도 대학별 수시2차 지원현황'!N6 -> 3362 | N5: 5.8195719 | O5: 5.9678457 | P5: 0.14827379 | Q5: 3818 | R5: 3734 | S5: 1 | T5: -84
A6: 한양여자대학교M | B6: 2426 | C6: 2280 | D6: 2314 | E6: -146 | F6: 697 | G6: 640 | H6: 659 | I6: -57 | J6: 5464 | K6: 6725 | L6: ='2026학년도 대학별 수시2차 지원현황'!M7 -> 614 | M6: ='2026학년도 대학별 수시2차 지원현황'!N7 -> 6111 | N6: 7.8393113 | O6: 10.507812 | P6: 2.6685012 | Q6: 5527 | R6: 6827 | S6: 1 | T6: 1300
A7: 동서울대학교M | B7: 2289 | C7: 2289 | D7: 2226 | E7: 0 | F7: 329 | G7: 342 | H7: 376 | I7: 13 | J7: 2905 | K7: 3414 | L7: ='2026학년도 대학별 수시2차 지원현황'!M8 -> 464 | M7: ='2026학년도 대학별 수시2차 지원현황'!N8 -> 2950 | N7: 8.8297872 | O7: 9.9824561 | P7: 1.1526689 | Q7: 2905 | R7: 3414 | S7: 1 | T7: 509
A8: 연성대학교M | B8: 2212 | C8: 2216 | D8: 2191 | E8: 4 | F8: 583 | G8: 590 | H8: 587 | I8: 7 | J8: 5672 | K8: 7008 | L8: ='2026학년도 대학별 수시2차 지원현황'!M9 -> 1121 | M8: ='2026학년도 대학별 수시2차 지원현황'!N9 -> 5887 | N8: 9.728988 | O8: 11.877966 | P8: 2.1489781 | Q8: 5676 | R8: 7019 | S8: 1 | T8: 1343
A9: 부천대학교 | B9: 2191 | C9: 2181 | D9: 2130 | E9: -10 | F9: 642 | G9: 623 | H9: 579 | I9: -19 | J9: 6531 | K9: 6407 | L9: ='2026학년도 대학별 수시2차 지원현황'!M10 -> 818 | M9: ='2026학년도 대학별 수시2차 지원현황'!N10 -> 5589 | N9: 10.172897 | O9: 10.284109 | P9: 0.11121195 | Q9: 6924 | R9: 6827 | S9: 1 | T9: -97
A10: 대림대학교M | B10: 2167 | C10: 2164 | D10: 2190 | E10: -3 | F10: 468 | G10: 468 | H10: 480 | I10: 0 | J10: 2322 | K10: 3388 | L10: ='2026학년도 대학별 수시2차 지원현황'!M11 -> 479 | M10: ='2026학년도 대학별 수시2차 지원현황'!N11 -> 2909 | N10: 4.9615385 | O10: 7.2393162 | P10: 2.2777778 | Q10: 2436 | R10: 3534 | S10: 1 | T10: 1098
A11: 유한대학교 | B11: 1703 | C11: 1695 | D11: 1691 | E11: -8 | F11: 231 | G11: 212 | H11: 263 | I11: -19 | J11: 2745 | K11: 3120 | L11: ='2026학년도 대학별 수시2차 지원현황'!M12 -> 467 | M11: ='2026학년도 대학별 수시2차 지원현황'!N12 -> 2653 | N11: 11.883117 | O11: 14.716981 | P11: 2.8338642 | Q11: 2926 | R11: 3307 | S11: 1 | T11: 381
A12: 경인여자대학교M | B12: 1305 | C12: 1305 | D12: 1305 | E12: 0 | F12: 242 | G12: 257 | H12: 233 | I12: 15 | J12: 2204 | K12: 2699 | L12: ='2026학년도 대학별 수시2차 지원현황'!M13 -> 333 | M12: ='2026학년도 대학별 수시2차 지원현황'!N13 -> 2366 | N12: 9.107438 | O12: 10.501946 | P12: 1.3945075 | Q12: 2526 | R12: 2986 | S12: 1 | T12: 460
A13: 재능대학교M | B13: 1313 | C13: 1279 | D13: 1237 | E13: -34 | F13: 241 | G13: 225 | H13: 214 | I13: -16 | J13: 1751 | K13: 1840 | L13: ='2026학년도 대학별 수시2차 지원현황'!M14 -> 318 | M13: ='2026학년도 대학별 수시2차 지원현황'!N14 -> 1522 | N13: 7.2655602 | O13: 8.1777778 | P13: 0.91221761 | Q13: 1772 | R13: 1868 | S13: 1 | T13: 96
A14: 김포대학교M | B14: 852 | C14: 822 | D14: 822 | E14: -30 | F14: 293 | G14: 183 | H14: 64 | I14: -110 | J14: 1222 | K14: 1929 | L14: ='2026학년도 대학별 수시2차 지원현황'!M15 -> 77 | M14: ='2026학년도 대학별 수시2차 지원현황'!N15 -> 1852 | N14: 4.1706485 | O14: 10.540984 | P14: 6.3703351 | Q14: 1246 | R14: 1937 | S14: 1 | T14: 691

Sheet 학과별 원서접수
Z1: 정원외
A2: 일반 | C2: 모집인원 | F2: =TODAY() -> 45972 | N2: 농어촌 | T2: 수급자 | Z2: 전문대/북한이탈주민 | AE2: 특성화고 | AK2: 일반고
A3: 계열 | B3: 모집단위 | C3: 2024학년도 | D3: 2025학년도 | E3: 모집인원 | F3: 지원인원 | G3: 경쟁률 | H3: 일자별 누계 | I3: 최종 | J3: 2026학년도2 | K3: 증감 | L3: 전년 최종대비 | N3: 계열 | O3: 모집단위 | P3: 모집인원 | Q3: 지원인원 | R3: 경쟁률 | T3: 계열 | U3: 모집단위 | V3: 모집인원 | W3: 지원인원 | X3: 경쟁률 | Z3: 계열 | AA3: 학과 | AB3: 전문대졸 | AC3: 북한이탈주민 | AE3: 계열 | AF3: 모집단위 | AG3: 모집인원 | AH3: 지원인원 | AI3: 경쟁률 | AK3: 계열 | AL3: 모집단위 | AM3: 모집인원 | AN3: 지원인원 | AO3: 경쟁률
A4: 공학 | B4: 자유전공학부 | C4: - | D4: 16 | E4: =특성화고_경쟁률_현황__2[[#This Row],[모집인원]]+일반고_경쟁률_현황__4[[#This Row],[모집인원]] -> 16 | F4: =특성화고_경쟁률_현황__2[[#This Row],[지원인원]]+일반고_경쟁률_현황__4[[#This Row],[지원인원]] -> 13 | G4: =ROUND(AVERAGE(표26[[#This Row],[지원인원]]/표26[[#This Row],[모집인원]]),2)&" : 1" -> 0.81 : 1 | H4: =표26[[#This Row],[지원인원]] -> 13 | I4: =표26[[#This Row],[지원인원]] -> 13 | N4: 공학 | O4: 기계공학과 | P4: 1 | Q4: 2 | R4: 2.00 : 1 | T4: 공학 | U4: 기계공학과 | V4: 2 | W4: 2 | X4: 1.00 : 1 | Z4: 공학 | AA4: 기계공학과 | AB4: 0 | AC4: 0 | AE4: 공학 | AF4: 자유전공학부 | AG4: 4 | AH4: 4 | AI4: 1.00 : 1 | AK4: 공학 | AL4: 자유전공학부 | AM4: 12 | AN4: 9 | AO4: 0.75 : 1
A5: 공학 | B5: 기계공학과 | C5: 25 | D5: 23 | E5: =특성화고_경쟁률_현황__2[[#This Row],[모집인원]]+일반고_경쟁률_현황__4[[#This Row],[모집인원]] -> 23 | F5: =특성화고_경쟁률_현황__2[[#This Row],[지원인원]]+일반고_경쟁률_현황__4[[#This Row],[지원인원]] -> 24 | G5: =ROUND(AVERAGE(표26[[#This Row],[지원인원]]/표26[[#This Row],[모집인원]]),2)&" : 1" -> 1.04 : 1 | H5: =표26[[#This Row],[지원인원]] -> 24 | I5: =표26[[#This Row],[지원인원]] -> 24 | N5: 공학 | O5: 기계설계공학과 | P5: 1 | Q5: 0 | R5: 0.00 : 1 | T5: 공학 | U5: 기계설계공학과 | V5: 2 | W5: 0 | X5: 0.00 : 1 | Z5: 공학 | AA5: 기계설계공학과 | AB5: 1 | AC5: 0 | AE5: 공학 | AF5: 기계공학과 | AG5: 5 | AH5: 9 | AI5: 1.80 : 1 | AK5: 공학 | AL5: 기계공학과 | AM5: 18 | AN5: 15 | AO5: 0.83 : 1
A6: 공학 | B6: 기계설계공학과 | C6: 25 | D6: 23 | E6: =특성화고_경쟁률_현황__2[[#This Row],[모집인원]]+일반고_경쟁률_현황__4[[#This Row],[모집인원]] -> 23 | F6: =특성화고_경쟁률_현황__2[[#This Row],[지원인원]]+일반고_경쟁률_현황__4[[#This Row],[지원인원]] -> 15 | G6: =ROUND(AVERAGE(표26[[#This Row],[지원인원]]/표26[[#This Row],[모집인원]]),2)&" : 1" -> 0.65 : 1 | H6: =표26[[#This Row],[지원인원]] -> 15 | I6: =표26[[#This Row],[지원인원]] -> 15 | N6: 공학 | O6: 로봇자동화공학과 | P6: 1 | Q6: 0 | R6: 0.00 : 1 | T6: 공학 | U6: 로봇자동화공학과 | V6: 2 | W6: 0 | X6: 0.00 : 1 | Z6: 공학 | AA6: 로봇자동화공학과 | AB6: 0 | AC6: 0 | AE6: 공학 | AF6: 기계설계공학과 | AG6: 5 | AH6: 6 | AI6: 1.20 : 1 | AK6: 공학 | AL6: 기계설계공학과 | AM6: 18 | AN6: 9 | AO6: 0.50 : 1
A7: 공학 | B7: 로봇자동화공학과 | C7: 19 | D7: 20 | E7: =특성화고_경쟁률_현황__2[[#This Row],[모집인원]]+일반고_경쟁률_현황__4[[#This Row],[모집인원]] -> 20 | F7: =특성화고_경쟁률_현황__2[[#This Row],[지원인원]]+일반고_경쟁률_현황__4[[#This Row],[지원인원]] -> 9 | G7: =ROUND(AVERAGE(표26[[#This Row],[지원인원]]/표26[[#This Row],[모집인원]]),2)&" : 1" -> 0.45 : 1 | H7: =표26[[#This Row],[지원인원]] -> 9 | I7: =표26[[#This Row],[지원인원]] -> 9 | N7: 공학 | O7: 반도체기계정비학과 | P7: 1 | Q7: 0 | R7: 0.00 : 1 | T7: 공학 | U7: 반도체기계정비학과 | V7: 1 | W7: 3 | X7: 3.00 : 1 | Z7: 공학 | AA7: 반도체기계정비학과 | AB7: 0 | AC7: 0 | AE7: 공학 | AF7: 로봇자동화공학과 | AG7: 4 | AH7: 3 | AI7: 0.75 : 1 | AK7: 공학 | AL7: 로봇자동화공학과 | AM7: 16 | AN7: 6 | AO7: 0.38 : 1
A8: 공학 | B8: 반도체기계정비학과 | C8: 13 | D8: 15 | E8: =특성화고_경쟁률_현황__2[[#This Row],[모집인원]]+일반고_경쟁률_현황__4[[#This Row],[모집인원]] -> 15 | F8: =특성화고_경쟁률_현황__2[[#This Row],[지원인원]]+일반고_경쟁률_현황__4[[#This Row],[지원인원]] -> 14 | G8: =ROUND(AVERAGE(표26[[#This Row],[지원인원]]/표26[[#This Row],[모집인원]]),2)&" : 1" -> 0.93 : 1 | H8: =표26[[#This Row],[지원인원]] -> 14 | I8: =표26[[#This Row],[지원인원]] -> 14 | N8: 공학 | O8: 조선기계공학과 | P8: 1 | Q8: 1 | R8: 1.00 : 1 | T8: 공학 | U8: 조선기계공학과 | V8: 2 | W8: 1 | X8: 0.50 : 1 | Z8: 공학 | AA8: 조선기계공학과 | AB8: 0 | AC8: 0 | AE8: 공학 | AF8: 반도체기계정비학과 | AG8: 6 | AH8: 9 | AI8: 1.50 : 1 | AK8: 공학 | AL8: 반도체기계정비학과 | AM8: 9 | AN8: 5 | AO8: 0.56 : 1
A9: 공학 | B9: 조선기계공학과 | C9: 23 | D9: 23 | E9: =특성화고_경쟁률_현황__2[[#This Row],[모집인원]]+일반고_경쟁률_현황__4[[#This Row],[모집인원]] -> 23 | F9: =특성화고_경쟁률_현황__2[[#This Row],[지원인원]]+일반고_경쟁률_현황__4[[#This Row],[지원인원]] -> 27 | G9: =ROUND(AVERAGE(표26[[#This Row],[지원인원]]/표26[[#This Row],[모집인원]]),2)&" : 1" -> 1.17 : 1 | H9: =표26[[#This Row],[지원인원]] -> 27 | I9: =표26[[#This Row],[지원인원]] -> 27 | N9: 공학 | O9: 항공기계공학과 | P9: 1 | Q9: 0 | R9: 0.00 : 1 | T9: 공학 | U9: 항공기계공학과 | V9: 2 | W9: 8 | X9: 4.00 : 1 | Z9: 공학 | AA9: 항공기계공학과 | AB9: 1 | AC9: 0 | AE9: 공학 | AF9: 조선기계공학과 | AG9: 5 | AH9: 5 | AI9: 1.00 : 1 | AK9: 공학 | AL9: 조선기계공학과 | AM9: 18 | AN9: 22 | AO9: 1.22 : 1
A10: 공학 | B10: 항공기계공학과 | C10: 30 | D10: 30 | E10: =특성화고_경쟁률_현황__2[[#This Row],[모집인원]]+일반고_경쟁률_현황__4[[#This Row],[모집인원]]+C40 -> 30 | F10: =특성화고_경쟁률_현황__2[[#This Row],[지원인원]]+일반고_경쟁률_현황__4[[#This Row],[지원인원]] -> 33 | G10: =ROUND(AVERAGE(표26[[#This Row],[지원인원]]/표26[[#This Row],[모집인원]]),2)&" : 1" -> 1.1 : 1 | H10: =표26[[#This Row],[지원인원]] -> 33 | I10: =표26[[#This Row],[지원인원]] -> 33 | N10: 공학 | O10: 자동차공학과 | P10: 1 | Q10: 3 | R10: 3.00 : 1 | T10: 공학 | U10: 자동차공학과 | V10: 2 | W10: 2 | X10: 1.00 : 1 | Z10: 공학 | AA10: 자동차공학과 | AB10: 0 | AC10: 0 | AE10: 공학 | AF10: 항공기계공학과 | AG10: 8 | AH10: 13 | AI10: 1.63 : 1 | AK10: 공학 | AL10: 항공기계공학과 | AM10: 18 | AN10: 20 | AO10: 1.11 : 1
A11: 공학 | B11: 자동차공학과 | C11: 25 | D11: 23 | E11: =특성화고_경쟁률_현황__2[[#This Row],[모집인원]]+일반고_경쟁률_현황__4[[#This Row],[모집인원]] -> 23 | F11: =특성화고_경쟁률_현황__2[[#This Row],[지원인원]]+일반고_경쟁률_현황__4[[#This Row],[지원인원]] -> 25 | G11: =ROUND(AVERAGE(표26[[#This Row],[지원인원]]/표26[[#This Row],[모집인원]]),2)&" : 1" -> 1.09 : 1 | H11: =표26[[#This Row],[지원인원]] -> 25 | I11: =표26[[#This Row],[지원인원]] -> 25 | N11: 공학 | O11: 전기공학과 | P11: 1 | Q11: 2 | R11: 2.00 : 1 | T11: 공학 | U11: 전기공학과 | V11: 2 | W11: 1 | X11: 0.50 : 1 | Z11: 공학 | AA11: 전기공학과 | AB11: 2 | AC11: 0 | AE11: 공학 | AF11: 자동차공학과 | AG11: 8 | AH11: 10 | AI11: 1.25 : 1 | AK11: 공학 | AL11: 자동차공학과 | AM11: 15 | AN11: 15 | AO11: 1.00 : 1
A12: 공학 | B12: 전기공학과 | C12: 25 | D12: 21 | E12: =특성화고_경쟁률_현황__2[[#This Row],[모집인원]]+일반고_경쟁률_현황__4[[#This Row],[모집인원]] -> 21 | F12: =특성화고_경쟁률_현황__2[[#This Row],[지원인원]]+일반고_경쟁률_현황__4[[#This Row],[지원인원]] -> 35 | G12: =ROUND(AVERAGE(표26[[#This Row],[지원인원]]/표26[[#This Row],[모집인원]]),2)&" : 1" -> 1.67 : 1 | H12: =표26[[#This Row],[지원인원]] -> 35 | I12: =표26[[#This Row],[지원인원]] -> 35 | N12: 공학 | O12: 전자공학과 | P12: 1 | Q12: 0 | R12: 0.00 : 1 | T12: 공학 | U12: 전자공학과 | V12: 2 | W12: 0 | X12: 0.00 : 1 | Z12: 공학 | AA12: 전자공학과 | AB12: 0 | AC12: 0 | AE12: 공학 | AF12: 전기공학과 | AG12: 5 | AH12: 16 | AI12: 3.20 : 1 | AK12: 공학 | AL12: 전기공학과 | AM12: 16 | AN12: 19 | AO12: 1.19 : 1
A13: 공학 | B13: 전자공학과 | C13: 25 | D13: 23 | E13: =특성화고_경쟁률_현황__2[[#This Row],[모집인원]]+일반고_경쟁률_현황__4[[#This Row],[모집인원]] -> 23 | F13: =특성화고_경쟁률_현황__2[[#This Row],[지원인원]]+일반고_경쟁률_현황__4[[#This Row],[지원인원]] -> 24 | G13: =ROUND(AVERAGE(표26[[#This Row],[지원인원]]/표26[[#This Row],[모집인원]]),2)&" : 1" -> 1.04 : 1 | H13: =표26[[#This Row],[지원인원]] -> 24 | I13: =표26[[#This Row],[지원인원]] -> 24 | N13: 공학 | O13: 정보통신공학과 | P13: 1 | Q13: 1 | R13: 1.00 : 1 | T13: 공학 | U13: 정보통신공학과 | V13: 2 | W13: 0 | X13: 0.00 : 1 | Z13: 공학 | AA13: 정보통신공학과 | AB13: 0 | AC13: 0 | AE13: 공학 | AF13: 전자공학과 | AG13: 5 | AH13: 11 | AI13: 2.20 : 1 | AK13: 공학 | AL13: 전자공학과 | AM13: 18 | AN13: 13 | AO13: 0.72 : 1
A14: 공학 | B14: 정보통신공학과 | C14: 30 | D14: 30 | E14: =특성화고_경쟁률_현황__2[[#This Row],[모집인원]]+일반고_경쟁률_현황__4[[#This Row],[모집인원]] -> 30 | F14: =특성화고_경쟁률_현황__2[[#This Row],[지원인원]]+일반고_경쟁률_현황__4[[#This Row],[지원인원]] -> 9 | G14: =ROUND(AVERAGE(표26[[#This Row],[지원인원]]/표26[[#This Row],[모집인원]]),2)&" : 1" -> 0.3 : 1 | H14: =표26[[#This Row],[지원인원]] -> 9 | I14: =표26[[#This Row],[지원인원]] -> 9 | N14: 공학 | O14: 컴퓨터정보공학과 | P14: 1 | Q14: 0 | R14: 0.00 : 1 | T14: 공학 | U14: 컴퓨터정보공학과 | V14: 2 | W14: 1 | X14: 0.50 : 1 | Z14: 공학 | AA14: 컴퓨터정보공학과 | AB14: 0 | AC14: 0 | AE14: 공학 | AF14: 정보통신공학과 | AG14: 6 | AH14: 5 | AI14: 0.83 : 1 | AK14: 공학 | AL14: 정보통신공학과 | AM14: 24 | AN14: 4 | AO14: 0.17 : 1
A15: 공학 | B15: 컴퓨터정보공학과 | C15: 25 | D15: 23 | E15: =특성화고_경쟁률_현황__2[[#This Row],[모집인원]]+일반고_경쟁률_현황__4[[#This Row],[모집인원]] -> 23 | F15: =특성화고_경쟁률_현황__2[[#This Row],[지원인원]]+일반고_경쟁률_현황__4[[#This Row],[지원인원]] -> 8 | G15: =ROUND(AVERAGE(표26[[#This Row],[지원인원]]/표26[[#This Row],[모집인원]]),2)&" : 1" -> 0.35 : 1 | H15: =표26[[#This Row],[지원인원]] -> 8 | I15: =표26[[#This Row],[지원인원]] -> 8 | N15: 공학 | O15: 컴퓨터시스템공학과 | P15: 1 | Q15: 0 | R15: 0.00 : 1 | T15: 공학 | U15: 컴퓨터시스템공학과 | V15: 2 | W15: 1 | X15: 0.50 : 1 | Z15: 공학 | AA15: 컴퓨터시스템공학과 | AB15: 0 | AC15: 0 | AE15: 공학 | AF15: 컴퓨터정보공학과 | AG15: 4 | AH15: 1 | AI15: 0.25 : 1 | AK15: 공학 | AL15: 컴퓨터정보공학과 | AM15: 19 | AN15: 7 | AO15: 0.37 : 1
A16: 공학 | B16: 컴퓨터시스템공학과 | C16: 25 | D16: 23 | E16: =특성화고_경쟁률_현황__2[[#This Row],[모집인원]]+일반고_경쟁률_현황__4[[#This Row],[모집인원]] -> 23 | F16: =특성화고_경쟁률_현황__2[[#This Row],[지원인원]]+일반고_경쟁률_현황__4[[#This Row],[지원인원]] -> 15 | G16: =ROUND(AVERAGE(표26[[#This Row],[지원인원]]/표26[[#This Row],[모집인원]]),2)&" : 1" -> 0.65 : 1 | H16: =표26[[#This Row],[지원인원]] -> 15 | I16: =표26[[#This Row],[지원인원]] -> 15 | N16: 공학 | O16: 디지털마케팅공학과 | P16: 1 | Q16: 0 | R16: 0.00 : 1 | T16: 공학 | U16: 디지털마케팅공학과 | V16: 2 | W16: 2 | X16: 1.00 : 1 | Z16: 공학 | AA16: 디지털마케팅공학과 | AB16: 0 | AC16: 0 | AE16: 공학 | AF16: 컴퓨터시스템공학과 | AG16: 5 | AH16: 5 | AI16: 1.00 : 1 | AK16: 공학 | AL16: 컴퓨터시스템공학과 | AM16: 18 | AN16: 10 | AO16: 0.56 : 1
A17: 공학 | B17: 디지털마케팅공학과 | C17: 13 | D17: 15 | E17: =특성화고_경쟁률_현황__2[[#This Row],[모집인원]]+일반고_경쟁률_현황__4[[#This Row],[모집인원]] -> 15 | F17: =특성화고_경쟁률_현황__2[[#This Row],[지원인원]]+일반고_경쟁률_현황__4[[#This Row],[지원인원]] -> 6 | G17: =ROUND(AVERAGE(표26[[#This Row],[지원인원]]/표26[[#This Row],[모집인원]]),2)&" : 1" -> 0.4 : 1 | H17: =표26[[#This Row],[지원인원]] -> 6 | I17: =표26[[#This Row],[지원인원]] -> 6 | N17: 공학 | O17: 건설환경공학과 | P17: 1 | Q17: 0 | R17: 0.00 : 1 | T17: 공학 | U17: 건설환경공학과 | V17: 2 | W17: 1 | X17: 0.50 : 1 | Z17: 공학 | AA17: 건설환경공학과 | AB17: 0 | AC17: 0 | AE17: 공학 | AF17: 디지털마케팅공학과 | AG17: 3 | AH17: 2 | AI17: 0.67 : 1 | AK17: 공학 | AL17: 디지털마케팅공학과 | AM17: 12 | AN17: 4 | AO17: 0.33 : 1
A18: 공학 | B18: 건설환경공학과 | C18: 24 | D18: 22 | E18: =특성화고_경쟁률_현황__2[[#This Row],[모집인원]]+일반고_경쟁률_현황__4[[#This Row],[모집인원]] -> 22 | F18: =특성화고_경쟁률_현황__2[[#This Row],[지원인원]]+일반고_경쟁률_현황__4[[#This Row],[지원인원]] -> 12 | G18: =ROUND(AVERAGE(표26[[#This Row],[지원인원]]/표26[[#This Row],[모집인원]]),2)&" : 1" -> 0.55 : 1 | H18: =표26[[#This Row],[지원인원]] -> 12 | I18: =표26[[#This Row],[지원인원]] -> 12 | N18: 공학 | O18: 공간정보빅데이터학과 | P18: 1 | Q18: 1 | R18: 1.00 : 1 | T18: 공학 | U18: 공간정보빅데이터학과 | V18: 2 | W18: 0 | X18: 0.00 : 1 | Z18: 공학 | AA18: 공간정보빅데이터학과 | AB18: 0 | AC18: 0 | AE18: 공학 | AF18: 건설환경공학과 | AG18: 4 | AH18: 3 | AI18: 0.75 : 1 | AK18: 공학 | AL18: 건설환경공학과 | AM18: 18 | AN18: 9 | AO18: 0.50 : 1
A19: 공학 | B19: 공간정보빅데이터학과 | C19: 18 | D19: 20 | E19: =특성화고_경쟁률_현황__2[[#This Row],[모집인원]]+일반고_경쟁률_현황__4[[#This Row],[모집인원]] -> 20 | F19: =특성화고_경쟁률_현황__2[[#This Row],[지원인원]]+일반고_경쟁률_현황__4[[#This Row],[지원인원]] -> 8 | G19: =ROUND(AVERAGE(표26[[#This Row],[지원인원]]/표26[[#This Row],[모집인원]]),2)&" : 1" -> 0.4 : 1 | H19: =표26[[#This Row],[지원인원]] -> 8 | I19: =표26[[#This Row],[지원인원]] -> 8 | N19: 공학 | O19: 화학생명공학과 | P19: 1 | Q19: 1 | R19: 1.00 : 1 | T19: 공학 | U19: 화학생명공학과 | V19: 2 | W19: 2 | X19: 1.00 : 1 | Z19: 공학 | AA19: 화학생명공학과 | AB19: 1 | AC19: 0 | AE19: 공학 | AF19: 공간정보빅데이터학과 | AG19: 4 | AH19: 3 | AI19: 0.75 : 1 | AK19: 공학 | AL19: 공간정보빅데이터학과 | AM19: 16 | AN19: 5 | AO19: 0.31 : 1
A20: 공학 | B20: 화학생명공학과 | C20: 25 | D20: 30 | E20: =특성화고_경쟁률_현황__2[[#This Row],[모집인원]]+일반고_경쟁률_현황__4[[#This Row],[모집인원]] -> 30 | F20: =특성화고_경쟁률_현황__2[[#This Row],[지원인원]]+일반고_경쟁률_현황__4[[#This Row],[지원인원]] -> 15 | G20: =ROUND(AVERAGE(표26[[#This Row],[지원인원]]/표26[[#This Row],[모집인원]]),2)&" : 1" -> 0.5 : 1 | H20: =표26[[#This Row],[지원인원]] -> 15 | I20: =표26[[#This Row],[지원인원]] -> 15 | N20: 공학 | O20: 재료공학과 | P20: 1 | Q20: 0 | R20: 0.00 : 1 | T20: 공학 | U20: 재료공학과 | V20: 2 | W20: 1 | X20: 0.50 : 1 | Z20: 공학 | AA20: 재료공학과 | AB20: 0 | AC20: 0 | AE20: 공학 | AF20: 화학생명공학과 | AG20: 6 | AH20: 6 | AI20: 1.00 : 1 | AK20: 공학 | AL20: 화학생명공학과 | AM20: 24 | AN20: 9 | AO20: 0.38 : 1
A21: 공학 | B21: 재료공학과 | C21: 25 | D21: 22 | E21: =특성화고_경쟁률_현황__2[[#This Row],[모집인원]]+일반고_경쟁률_현황__4[[#This Row],[모집인원]] -> 22 | F21: =특성화고_경쟁률_현황__2[[#This Row],[지원인원]]+일반고_경쟁률_현황__4[[#This Row],[지원인원]] -> 16 | G21: =ROUND(AVERAGE(표26[[#This Row],[지원인원]]/표26[[#This Row],[모집인원]]),2)&" : 1" -> 0.73 : 1 | H21: =표26[[#This Row],[지원인원]] -> 16 | I21: =표26[[#This Row],[지원인원]] -> 16 | N21: 공학 | O21: 건축학과 | P21: 1 | Q21: 0 | R21: 0.00 : 1 | T21: 공학 | U21: 건축학과 | V21: 2 | W21: 2 | X21: 1.00 : 1 | Z21: 공학 | AA21: 건축학과 | AB21: 0 | AC21: 0 | AE21: 공학 | AF21: 재료공학과 | AG21: 4 | AH21: 3 | AI21: 0.75 : 1 | AK21: 공학 | AL21: 재료공학과 | AM21: 18 | AN21: 13 | AO21: 0.72 : 1
A22: 공학 | B22: 건축학과 | C22: 23 | D22: 23 | E22: =특성화고_경쟁률_현황__2[[#This Row],[모집인원]]+일반고_경쟁률_현황__4[[#This Row],[모집인원]] -> 23 | F22: =특성화고_경쟁률_현황__2[[#This Row],[지원인원]]+일반고_경쟁률_현황__4[[#This Row],[지원인원]] -> 19 | G22: =ROUND(AVERAGE(표26[[#This Row],[지원인원]]/표26[[#This Row],[모집인원]]),2)&" : 1" -> 0.83 : 1 | H22: =표26[[#This Row],[지원인원]] -> 19 | I22: =표26[[#This Row],[지원인원]] -> 19 | N22: 공학 | O22: 실내건축학과 | P22: 1 | Q22: 0 | R22: 0.00 : 1 | T22: 공학 | U22: 실내건축학과 | V22: 2 | W22: 3 | X22: 1.50 : 1 | Z22: 공학 | AA22: 실내건축학과 | AB22: 0 | AC22: 0 | AE22: 공학 | AF22: 건축학과 | AG22: 5 | AH22: 6 | AI22: 1.20 : 1 | AK22: 공학 | AL22: 건축학과 | AM22: 18 | AN22: 13 | AO22: 0.72 : 1
... A25: 예체능 | B25: 패션디자인학과 | C25: 18 | D25: 18 | E25: =특성화고_경쟁률_현황__2[[#This Row],[모집인원]]+일반고_경쟁률_현황__4[[#This Row],[모집인원]] -> 18 | F25: =특성화고_경쟁률_현황__2[[#This Row],[지원인원]]+일반고_경쟁률_현황__4[[#This Row],[지원인원]] -> 17 | G25: =ROUND(AVERAGE(표26[[#This Row],[지원인원]]/표26[[#This Row],[모집인원]]),2)&" : 1" -> 0.94 : 1 | H25: =표26[[#This Row],[지원인원]] -> 17 | I25: =표26[[#This Row],[지원인원]] -> 17 | N25: 인문사회 | O25: 항공운항과 | P25: 3 | Q25: 8 | R25: 2.67 : 1 | T25: 인문사회 | U25: 항공운항과 | V25: 3 | W25: 16 | X25: 5.33 : 1 | Z25: 인문사회 | AA25: 항공운항과 | AB25: 4 | AC25: 0 | AE25: 예체능 | AF25: 패션디자인학과 | AG25: 4 | AH25: 3 | AI25: 0.75 : 1 | AK25: 예체능 | AL25: 패션디자인학과 | AM25: 14 | AN25: 14 | AO25: 1.00 : 1
A26: 인문사회 | B26: 항공운항과 | C26: 40 | D26: 40 | E26: =특성화고_경쟁률_현황__2[[#This Row],[모집인원]]+일반고_경쟁률_현황__4[[#This Row],[모집인원]]+C41 -> 40 | F26: =특성화고_경쟁률_현황__2[[#This Row],[지원인원]]+일반고_경쟁률_현황__4[[#This Row],[지원인원]] -> 275 | G26: =ROUND(AVERAGE(표26[[#This Row],[지원인원]]/표26[[#This Row],[모집인원]]),2)&" : 1" -> 6.88 : 1 | H26: =표26[[#This Row],[지원인원]] -> 275 | I26: =표26[[#This Row],[지원인원]] -> 275 | N26: 인문사회 | O26: 항공경영학과 | P26: 1 | Q26: 2 | R26: 2.00 : 1 | T26: 인문사회 | U26: 항공경영학과 | V26: 2 | W26: 2 | X26: 1.00 : 1 | Z26: 인문사회 | AA26: 항공경영학과 | AB26: 1 | AC26: 0 | AE26: 인문사회 | AF26: 항공운항과 | AG26: 3 | AH26: 19 | AI26: 6.33 : 1 | AK26: 인문사회 | AL26: 항공운항과 | AM26: 32 | AN26: 256 | AO26: 8.00 : 1
A27: 인문사회 | B27: 항공경영학과 | C27: 25 | D27: 23 | E27: =특성화고_경쟁률_현황__2[[#This Row],[모집인원]]+일반고_경쟁률_현황__4[[#This Row],[모집인원]] -> 23 | F27: =특성화고_경쟁률_현황__2[[#This Row],[지원인원]]+일반고_경쟁률_현황__4[[#This Row],[지원인원]] -> 35 | G27: =ROUND(AVERAGE(표26[[#This Row],[지원인원]]/표26[[#This Row],[모집인원]]),2)&" : 1" -> 1.52 : 1 | H27: =표26[[#This Row],[지원인원]] -> 35 | I27: =표26[[#This Row],[지원인원]] -> 35 | N27: 인문사회 | O27: 관광경영학과 | P27: 1 | Q27: 1 | R27: 1.00 : 1 | T27: 인문사회 | U27: 관광경영학과 | V27: 1 | W27: 3 | X27: 3.00 : 1 | Z27: 인문사회 | AA27: 관광경영학과 | AB27: 0 | AC27: 0 | AE27: 인문사회 | AF27: 항공경영학과 | AG27: 5 | AH27: 12 | AI27: 2.40 : 1 | AK27: 인문사회 | AL27: 항공경영학과 | AM27: 18 | AN27: 23 | AO27: 1.28 : 1
A28: 인문사회 | B28: 관광경영학과 | C28: 23 | D28: 22 | E28: =특성화고_경쟁률_현황__2[[#This Row],[모집인원]]+일반고_경쟁률_현황__4[[#This Row],[모집인원]] -> 22 | F28: =특성화고_경쟁률_현황__2[[#This Row],[지원인원]]+일반고_경쟁률_현황__4[[#This Row],[지원인원]] -> 38 | G28: =ROUND(AVERAGE(표26[[#This Row],[지원인원]]/표26[[#This Row],[모집인원]]),2)&" : 1" -> 1.73 : 1 | H28: =표26[[#This Row],[지원인원]] -> 38 | I28: =표26[[#This Row],[지원인원]] -> 38 | N28: 인문사회 | O28: 경영비서학과 | P28: 1 | Q28: 0 | R28: 0.00 : 1 | T28: 인문사회 | U28: 경영비서학과 | V28: 1 | W28: 3 | X28: 3.00 : 1 | Z28: 인문사회 | AA28: 경영비서학과 | AB28: 0 | AC28: 0 | AE28: 인문사회 | AF28: 관광경영학과 | AG28: 4 | AH28: 11 | AI28: 2.75 : 1 | AK28: 인문사회 | AL28: 관광경영학과 | AM28: 18 | AN28: 27 | AO28: 1.50 : 1
A29: 인문사회 | B29: 경영비서학과 | C29: 23 | D29: 22 | E29: =특성화고_경쟁률_현황__2[[#This Row],[모집인원]]+일반고_경쟁률_현황__4[[#This Row],[모집인원]] -> 22 | F29: =특성화고_경쟁률_현황__2[[#This Row],[지원인원]]+일반고_경쟁률_현황__4[[#This Row],[지원인원]] -> 18 | G29: =ROUND(AVERAGE(표26[[#This Row],[지원인원]]/표26[[#This Row],[모집인원]]),2)&" : 1" -> 0.82 : 1 | H29: =표26[[#This Row],[지원인원]] -> 18 | I29: =표26[[#This Row],[지원인원]] -> 18 | N29: 인문사회 | O29: 호텔경영학과 | P29: 1 | Q29: 0 | R29: 0.00 : 1 | T29: 인문사회 | U29: 호텔경영학과 | V29: 1 | W29: 2 | X29: 2.00 : 1 | Z29: 인문사회 | AA29: 호텔경영학과 | AB29: 0 | AC29: 0 | AE29: 인문사회 | AF29: 경영비서학과 | AG29: 4 | AH29: 9 | AI29: 2.25 : 1 | AK29: 인문사회 | AL29: 경영비서학과 | AM29: 18 | AN29: 9 | AO29: 0.50 : 1
A30: 인문사회 | B30: 호텔경영학과 | C30: 24 | D30: 22 | E30: =특성화고_경쟁률_현황__2[[#This Row],[모집인원]]+일반고_경쟁률_현황__4[[#This Row],[모집인원]] -> 22 | F30: =특성화고_경쟁률_현황__2[[#This Row],[지원인원]]+일반고_경쟁률_현황__4[[#This Row],[지원인원]] -> 21 | G30: =ROUND(AVERAGE(표26[[#This Row],[지원인원]]/표26[[#This Row],[모집인원]]),2)&" : 1" -> 0.95 : 1 | H30: =표26[[#This Row],[지원인원]] -> 21 | I30: =표26[[#This Row],[지원인원]] -> 21 | N30: 인문사회 | O30: 물류시스템학과 | P30: 1 | Q30: 0 | R30: 0.00 : 1 | T30: 인문사회 | U30: 물류시스템학과 | V30: 2 | W30: 2 | X30: 1.00 : 1 | Z30: 인문사회 | AA30: 물류시스템학과 | AB30: 0 | AC30: 0 | AE30: 인문사회 | AF30: 호텔경영학과 | AG30: 6 | AH30: 6 | AI30: 1.00 : 1 | AK30: 인문사회 | AL30: 호텔경영학과 | AM30: 16 | AN30: 15 | AO30: 0.94 : 1
A31: 인문사회 | B31: 물류시스템학과 | C31: 13 | D31: 15 | E31: =특성화고_경쟁률_현황__2[[#This Row],[모집인원]]+일반고_경쟁률_현황__4[[#This Row],[모집인원]] -> 15 | F31: =특성화고_경쟁률_현황__2[[#This Row],[지원인원]]+일반고_경쟁률_현황__4[[#This Row],[지원인원]] -> 9 | G31: =ROUND(AVERAGE(표26[[#This Row],[지원인원]]/표26[[#This Row],[모집인원]]),2)&" : 1" -> 0.6 : 1 | H31: =표26[[#This Row],[지원인원]] -> 9 | I31: =표26[[#This Row],[지원인원]] -> 9 | N31: 예체능 | O31: 스포츠헬스케어학과 | P31: 1 | Q31: 0 | R31: 0.00 : 1 | T31: 예체능 | U31: 스포츠헬스케어학과 | V31: 2 | W31: 3 | X31: 1.50 : 1 | Z31: 예체능 | AA31: 스포츠헬스케어학과 | AB31: 1 | AC31: 0 | AE31: 인문사회 | AF31: 물류시스템학과 | AG31: 3 | AH31: 1 | AI31: 0.33 : 1 | AK31: 인문사회 | AL31: 물류시스템학과 | AM31: 12 | AN31: 8 | AO31: 0.67 : 1
A32: 예체능 | B32: 스포츠헬스케어학과 | C32: 14 | D32: 15 | E32: =특성화고_경쟁률_현황__2[[#This Row],[모집인원]]+일반고_경쟁률_현황__4[[#This Row],[모집인원]] -> 15 | F32: =특성화고_경쟁률_현황__2[[#This Row],[지원인원]]+일반고_경쟁률_현황__4[[#This Row],[지원인원]] -> 23 | G32: =ROUND(AVERAGE(표26[[#This Row],[지원인원]]/표26[[#This Row],[모집인원]]),2)&" : 1" -> 1.53 : 1 | H32: =표26[[#This Row],[지원인원]] -> 23 | I32: =표26[[#This Row],[지원인원]] -> 23 | N32: 총계 | O32: 총계 | P32: 30 | Q32: 22 | R32: 0.73 : 1 | T32: 총계 | U32: 총계 | V32: 53 | W32: 61 | X32: 1.15 : 1 | Z32: 합계 | AA32: 합계 | AB32: 11 | AC32: 0 | AE32: 예체능 | AF32: 스포츠헬스케어학과 | AG32: 3 | AH32: 4 | AI32: 1.33 : 1 | AK32: 예체능 | AL32: 스포츠헬스케어학과 | AM32: 12 | AN32: 19 | AO32: 1.58 : 1
A33: 총계 | B33: 총계 | C33: =SUM(C4:C32) -> 639 | D33: =SUM(D4:D32) -> 644 | E33: =SUM(E4:E32) -> 644 | F33: =SUM(F4:F32) -> 800 | G33: =ROUND(AVERAGE(표26[[#This Row],[지원인원]]/표26[[#This Row],[모집인원]]),2)&" : 1" -> 1.24 : 1 | H33: =표26[[#This Row],[지원인원]] -> 800 | I33: =표26[[#This Row],[지원인원]] -> 800 | AE33: 총계 | AF33: 총계 | AG33: 137 | AH33: 199 | AI33: 1.45 : 1 | AK33: 총계 | AL33: 총계 | AM33: 498 | AN33: 601 | AO33: 1.21 : 1
A38: 어학특기자
A39: 계열 | B39: 모집단위 | C39: 모집인원 | D39: 지원인원 | E39: 경쟁률
A40: 공학 | B40: 항공기계공학과 | C40: 4 | D40: 3 | E40: 0.75 : 1
A41: 인문사회 | B41: 항공운항과 | C41: 5 | D41: 19 | E41: 3.80 : 1 | AE41: =AM33+AG33+V32+P32+C42 -> 727
A42: 총계 | B42: 총계 | C42: 9 | D42: 22 | E42: 2.44 : 1
A44: 구분 | C44: 정원내 | G44: 정원외
C45: 일반고 | E45: 특성화고 | G45: 농어촌 | I45: 수급자 | K45: 전문대 | L45: 북한이탈주민
A46: 계열 | B46: 모집단위 | C46: 모집인원 | D46: 지원인원 | E46: 모집인원2 | F46: 지원인원3 | G46: 모집인원22 | H46: 지원인원33 | I46: 모집인원2 | J46: 지원인원3 | K46: 지원인원4 | L46: 지원인원5 | M46: 총합계
A47: 공학 | B47: 자유전공학부 | C47: =AM4 -> 12 | D47: =AN4 -> 9 | E47: =AG4 -> 4 | F47: =AH4 -> 4 | M47: =표2[[#This Row],[지원인원]]+표2[[#This Row],[지원인원3]] -> 13
...
